Some weights of BertForSequenceClassification were not initialized from the model checkpoint at bert-base-uncased and are newly initialized: ['classifier.bias', 'classifier.weight']
You should probably TRAIN this model on a down-stream task to be able to use it for predictions and inference.
[INFO] Group mapping used: {'black': 0, 'white': 1}
Parameter 'function'=<function df_map.<locals>.<lambda> at 0x7fe3ec2b2c00> of the transform datasets.arrow_dataset.Dataset._map_single couldn't be hashed properly, a random hash was used instead. Make sure your transforms and parameters are serializable with pickle or dill for the dataset fingerprinting and caching to work. If you reuse this transform, the caching mechanism will consider it to be different from the previous calls and recompute everything. This warning is only showed once. Subsequent hashing failures won't be showed.
Map: 100%|█████████████████████████████████████████████████████████████████████████████████████████████████████████████████████████████████████████████████████████████████████████████████████████████████████████████████████████████████████████████████████████████████████████████| 10000/10000 [00:02<00:00, 4326.83 examples/s]
[INFO] Group mapping used: {'black': 0, 'white': 1}
Map: 100%|█████████████████████████████████████████████████████████████████████████████████████████████████████████████████████████████████████████████████████████████████████████████████████████████████████████████████████████████████████████████████████████████████████████████████| 100/100 [00:00<00:00, 2697.01 examples/s]
{'train_runtime': 1.5125, 'train_samples_per_second': 198.348, 'train_steps_per_second': 13.884, 'train_loss': 0.05003319467817034, 'epoch': 3.0}

=== Iteration 1 ===
Traceback (most recent call last):
  File "/home/copresence/miniconda3/envs/NLP/lib/python3.12/site-packages/pandas/core/indexes/base.py", line 3805, in get_loc
    return self._engine.get_loc(casted_key)
           ^^^^^^^^^^^^^^^^^^^^^^^^^^^^^^^^
  File "index.pyx", line 167, in pandas._libs.index.IndexEngine.get_loc
  File "index.pyx", line 196, in pandas._libs.index.IndexEngine.get_loc
  File "pandas/_libs/hashtable_class_helper.pxi", line 7081, in pandas._libs.hashtable.PyObjectHashTable.get_item
  File "pandas/_libs/hashtable_class_helper.pxi", line 7089, in pandas._libs.hashtable.PyObjectHashTable.get_item
KeyError: 'bb_score'

The above exception was the direct cause of the following exception:

Traceback (most recent call last):
  File "/mnt/sda/david/activeAuditing/new_activeAuditing/AcitveAuditing_140725_refactored/main.py", line 55, in <module>
    main()
  File "/mnt/sda/david/activeAuditing/new_activeAuditing/AcitveAuditing_140725_refactored/main.py", line 51, in main
    runner.run()
  File "/mnt/sda/david/activeAuditing/new_activeAuditing/AcitveAuditing_140725_refactored/audit_run.py", line 89, in run
    self.D["disagreement"] = abs(self.D["bb_score"] - self.D["surrogate_score"])
                                 ~~~~~~^^^^^^^^^^^^
  File "/home/copresence/miniconda3/envs/NLP/lib/python3.12/site-packages/pandas/core/frame.py", line 4090, in __getitem__
    indexer = self.columns.get_loc(key)
              ^^^^^^^^^^^^^^^^^^^^^^^^^
  File "/home/copresence/miniconda3/envs/NLP/lib/python3.12/site-packages/pandas/core/indexes/base.py", line 3812, in get_loc
    raise KeyError(key) from err
KeyError: 'bb_score'
